Workbook

Sheet Instances
A1: Tasks | B1: Name
A2: 492 | B2: 1000genome-chameleon-12ch-250k-001
A3: 738 | B3: 1000genome-chameleon-18ch-250k-001
A4: 82 | B4: 1000genome-chameleon-2ch-250k-001
A5: 164 | B5: 1000genome-chameleon-4ch-250k-001
A6: 67 | B6: cycles-chameleon-1l-1c-9p-001
A7: 437 | B7: cycles-chameleon-2l-1c-12p-001
A8: 133 | B8: cycles-chameleon-2l-1c-9p-001
A9: 1091 | B9: cycles-chameleon-5l-1c-12p-001
A10: 41 | B10: epigenomics-chameleon-hep-1seq-100k-001
A11: 125 | B11: epigenomics-chameleon-ilmn-1seq-100k-001
A12: 507 | B12: epigenomics-chameleon-hep-6seq-100k-001
A13: 863 | B13: epigenomics-chameleon-ilmn-6seq-100k-001
... A29: 104 | B29: srasearch-chameleon-50a-003

Sheet Data
A1: Problem | B1: Benchmark | C1: Tasks | D1: Hosts | E1: Real HEFT_NC | F1: Real HEFT_DNC | G1: Real GA_NC | H1: Real GA_DNC | I1: Real HGA_(Ph2) | J1: Real HGA_(Ph1) | K1: Real GA^H | L1: Real HGA_(Ph2)^H | M1: Real HGA_(Ph1)^H | N1: HEFT_DNC vs HEFT_NC | O1: GA_NC vs HEFT_NC | P1: GA_DNC vs HEFT_NC | Q1: HGA_(Ph2) vs HEFT_NC | R1: HGA_(Ph1) vs HEFT_NC | S1: GA^H vs HEDT_NC | T1: HGA_(Ph2)^H vs HEFT_NC | U1: HGA_(Ph1)^H vs HEFT_NC | V1: Calculated HEFT_NC | W1: Calculated HEFT_DNC | X1: Calculated GA_NC | Y1: Calculated GA_DNC | Z1: Calculated HGA_(Ph2) | AA1: Calculated HGA_(Ph1) | AB1: Calculated HGA^H | AC1: Calculated HGA_(Ph2)^H | AD1: Calculated HGA_(Ph1)^H | AE1: accuracy HEFT_NC | AF1: accuracy HEFT_DNC | AG1: accuracy GA_NC | AH1: accuracy GA_DNC | AI1: accuracy HGA_(Ph2) | AJ1: accuracy HGA_(Ph1) | AK1: accuracy HGA^H | AL1: accuracy HGA_(Ph2)^H | AM1: accuracy HGA_(Ph1)^H
A2: =LEFT(B2,FIND("-",B2)-1) -> 1000genome | B2: 1000genome-chameleon-12ch-250k-001 | C2: =_xlfn.XLOOKUP(B2,Instances!$B$2:$B$29,Instances!$A$2:$A$29,,0,1) -> 492 | D2: 1 | E2: 34863.4 | F2: 34863.4 | G2: 34863.4 | H2: 34863.4 | I2: 34863.4 | J2: 34863.4 | K2: 34863.4 | L2: 34863.4 | M2: 34863.4 | N2: =(($E2-F2)/$E2) -> 0 | O2: =(($E2-G2)/$E2) -> 0 | P2: =(($E2-H2)/$E2) -> 0 | Q2: =(($E2-I2)/$E2) -> 0 | R2: =(($E2-J2)/$E2) -> 0 | S2: =(($E2-K2)/$E2) -> 0 | T2: =(($E2-L2)/$E2) -> 0 | U2: =(($E2-M2)/$E2) -> 0 | V2: 28130.2 | W2: 34863.3 | X2: 28130.2 | Y2: 34863.3 | Z2: 34863.3 | AA2: 34863.3 | AB2: 34863.3 | AC2: 34863.3 | AD2: 34863.3 | AE2: =Tabla13[[#This Row],[Calculated HEFT_NC]]/Tabla13[[#This Row],[Real HEFT_NC]] -> 0.80686909 | AF2: =Tabla13[[#This Row],[Calculated HEFT_DNC]]/Tabla13[[#This Row],[Real HEFT_DNC]] -> 0.99999713 | AG2: =Tabla13[[#This Row],[Calculated GA_NC]]/Tabla13[[#This Row],[Real GA_NC]] -> 0.80686909 | AH2: =Tabla13[[#This Row],[Calculated GA_DNC]]/Tabla13[[#This Row],[Real GA_DNC]] -> 0.99999713 | AI2: =Tabla13[[#This Row],[Calculated HGA_(Ph2)]]/Tabla13[[#This Row],[Real HGA_(Ph2)]] -> 0.99999713 | AJ2: =Tabla13[[#This Row],[Calculated HGA_(Ph1)]]/Tabla13[[#This Row],[Real HGA_(Ph1)]] -> 0.99999713 | AK2: =Tabla13[[#This Row],[Calculated HGA^H]]/Tabla13[[#This Row],[Real GA^H]] -> 0.99999713 | AL2: =Tabla13[[#This Row],[Calculated HGA_(Ph2)^H]]/Tabla13[[#This Row],[Real HGA_(Ph2)^H]] -> 0.99999713 | AM2: =Tabla13[[#This Row],[Calculated HGA_(Ph1)^H]]/Tabla13[[#This Row],[Real HGA_(Ph1)^H]] -> 0.99999713
A3: =LEFT(B3,FIND("-",B3)-1) -> 1000genome | B3: 1000genome-chameleon-12ch-250k-001 | C3: =_xlfn.XLOOKUP(B3,Instances!$B$2:$B$29,Instances!$A$2:$A$29,,0,1) -> 492 | D3: 2 | E3: 17473 | F3: 17432.2 | G3: 17457.49 | H3: 17432.18 | I3: 17432.17 | J3: 17432.16 | K3: 17432.14 | L3: 17432.19 | M3: 17432.1 | N3: =(($E3-F3)/$E3) -> 0.0023350312 | O3: =(($E3-G3)/$E3) -> 0.00088765524 | P3: =(($E3-H3)/$E3) -> 0.0023361758 | Q3: =(($E3-I3)/$E3) -> 0.0023367481 | R3: =(($E3-J3)/$E3) -> 0.0023373204 | S3: =(($E3-K3)/$E3) -> 0.0023384651 | T3: =(($E3-L3)/$E3) -> 0.0023356035 | U3: =(($E3-M3)/$E3) -> 0.0023407543 | V3: 14065.5 | W3: 17431.7 | X3: 14065.1 | Y3: 17431.6 | Z3: 17431.6 | AA3: 17431.67 | AB3: 17431.6 | AC3: 17431.6 | AD3: 17431.6 | AE3: =Tabla13[[#This Row],[Calculated HEFT_NC]]/Tabla13[[#This Row],[Real HEFT_NC]] -> 0.80498483 | AF3: =Tabla13[[#This Row],[Calculated HEFT_DNC]]/Tabla13[[#This Row],[Real HEFT_DNC]] -> 0.99997132 | AG3: =Tabla13[[#This Row],[Calculated GA_NC]]/Tabla13[[#This Row],[Real GA_NC]] -> 0.8056771 | AH3: =Tabla13[[#This Row],[Calculated GA_DNC]]/Tabla13[[#This Row],[Real GA_DNC]] -> 0.99996673 | AI3: =Tabla13[[#This Row],[Calculated HGA_(Ph2)]]/Tabla13[[#This Row],[Real HGA_(Ph2)]] -> 0.9999673 | AJ3: =Tabla13[[#This Row],[Calculated HGA_(Ph1)]]/Tabla13[[#This Row],[Real HGA_(Ph1)]] -> 0.99997189 | AK3: =Tabla13[[#This Row],[Calculated HGA^H]]/Tabla13[[#This Row],[Real GA^H]] -> 0.99996902 | AL3: =Tabla13[[#This Row],[Calculated HGA_(Ph2)^H]]/Tabla13[[#This Row],[Real HGA_(Ph2)^H]] -> 0.99996615 | AM3: =Tabla13[[#This Row],[Calculated HGA_(Ph1)^H]]/Tabla13[[#This Row],[Real HGA_(Ph1)^H]] -> 0.99997132
A4: =LEFT(B4,FIND("-",B4)-1) -> 1000genome | B4: 1000genome-chameleon-12ch-250k-001 | C4: =_xlfn.XLOOKUP(B4,Instances!$B$2:$B$29,Instances!$A$2:$A$29,,0,1) -> 492 | D4: 4 | E4: 8754.37 | F4: 8717.58 | G4: 8768.227 | H4: 8718.287 | I4: 8716.305 | J4: 8738.56 | K4: 8716.549 | L4: 8716.183 | M4: 8717.106 | N4: =(($E4-F4)/$E4) -> 0.0042024726 | O4: =(($E4-G4)/$E4) -> -0.0015828666 | P4: =(($E4-H4)/$E4) -> 0.0041217129 | Q4: =(($E4-I4)/$E4) -> 0.0043481141 | R4: =(($E4-J4)/$E4) -> 0.0018059552 | S4: =(($E4-K4)/$E4) -> 0.0043202423 | T4: =(($E4-L4)/$E4) -> 0.00436205 | U4: =(($E4-M4)/$E4) -> 0.004256617 | V4: 7033.69 | W4: 8717.19 | X4: 7034.818 | Y4: 8717.922 | Z4: 8715.942 | AA4: 8738.245 | AB4: 8716.196 | AC4: 8715.82 | AD4: 8716.777 | AE4: =Tabla13[[#This Row],[Calculated HEFT_NC]]/Tabla13[[#This Row],[Real HEFT_NC]] -> 0.80344902 | AF4: =Tabla13[[#This Row],[Calculated HEFT_DNC]]/Tabla13[[#This Row],[Real HEFT_DNC]] -> 0.99995526 | AG4: =Tabla13[[#This Row],[Calculated GA_NC]]/Tabla13[[#This Row],[Real GA_NC]] -> 0.80230792 | AH4: =Tabla13[[#This Row],[Calculated GA_DNC]]/Tabla13[[#This Row],[Real GA_DNC]] -> 0.99995813 | AI4: =Tabla13[[#This Row],[Calculated HGA_(Ph2)]]/Tabla13[[#This Row],[Real HGA_(Ph2)]] -> 0.99995835 | AJ4: =Tabla13[[#This Row],[Calculated HGA_(Ph1)]]/Tabla13[[#This Row],[Real HGA_(Ph1)]] -> 0.99996395 | AK4: =Tabla13[[#This Row],[Calculated HGA^H]]/Tabla13[[#This Row],[Real GA^H]] -> 0.9999595 | AL4: =Tabla13[[#This Row],[Calculated HGA_(Ph2)^H]]/Tabla13[[#This Row],[Real HGA_(Ph2)^H]] -> 0.99995835 | AM4: =Tabla13[[#This Row],[Calculated HGA_(Ph1)^H]]/Tabla13[[#This Row],[Real HGA_(Ph1)^H]] -> 0.99996226
A5: =LEFT(B5,FIND("-",B5)-1) -> 1000genome | B5: 1000genome-chameleon-12ch-250k-001 | C5: =_xlfn.XLOOKUP(B5,Instances!$B$2:$B$29,Instances!$A$2:$A$29,,0,1) -> 492 | D5: 8 | E5: 4378.4 | F5: 4360.29 | G5: 4427.855 | H5: 4370.431 | I5: 4359.59 | J5: 4461.262 | K5: 4359.306 | L5: 4358.137 | M5: 4360.29 | N5: =(($E5-F5)/$E5) -> 0.0041362141 | O5: =(($E5-G5)/$E5) -> -0.011295222 | P5: =(($E5-H5)/$E5) -> 0.0018200713 | Q5: =(($E5-I5)/$E5) -> 0.0042960899 | R5: =(($E5-J5)/$E5) -> -0.018925178 | S5: =(($E5-K5)/$E5) -> 0.0043609538 | T5: =(($E5-L5)/$E5) -> 0.0046279463 | U5: =(($E5-M5)/$E5) -> 0.0041362141 | V5: 3517.61 | W5: 4360.12 | X5: 3537.069 | Y5: 4370.24 | Z5: 4359.399 | AA5: 4461.055 | AB5: 4359.13 | AC5: 4357.919 | AD5: 4360.12 | AE5: =Tabla13[[#This Row],[Calculated HEFT_NC]]/Tabla13[[#This Row],[Real HEFT_NC]] -> 0.80340079 | AF5: =Tabla13[[#This Row],[Calculated HEFT_DNC]]/Tabla13[[#This Row],[Real HEFT_DNC]] -> 0.99996101 | AG5: =Tabla13[[#This Row],[Calculated GA_NC]]/Tabla13[[#This Row],[Real GA_NC]] -> 0.79882223 | AH5: =Tabla13[[#This Row],[Calculated GA_DNC]]/Tabla13[[#This Row],[Real GA_DNC]] -> 0.9999563 | AI5: =Tabla13[[#This Row],[Calculated HGA_(Ph2)]]/Tabla13[[#This Row],[Real HGA_(Ph2)]] -> 0.99995619 | AJ5: =Tabla13[[#This Row],[Calculated HGA_(Ph1)]]/Tabla13[[#This Row],[Real HGA_(Ph1)]] -> 0.9999536 | AK5: =Tabla13[[#This Row],[Calculated HGA^H]]/Tabla13[[#This Row],[Real GA^H]] -> 0.99995963 | AL5: =Tabla13[[#This Row],[Calculated HGA_(Ph2)^H]]/Tabla13[[#This Row],[Real HGA_(Ph2)^H]] -> 0.99994998 | AM5: =Tabla13[[#This Row],[Calculated HGA_(Ph1)^H]]/Tabla13[[#This Row],[Real HGA_(Ph1)^H]] -> 0.99996101
A6: =LEFT(B6,FIND("-",B6)-1) -> 1000genome | B6: 1000genome-chameleon-12ch-250k-001 | C6: =_xlfn.XLOOKUP(B6,Instances!$B$2:$B$29,Instances!$A$2:$A$29,,0,1) -> 492 | D6: 16 | E6: 2207.79 | F6: 2181.37 | G6: 2275.296 | H6: 2253.875 | I6: 2184.944 | J6: 2325.363 | K6: 2181.144 | L6: 2179.133 | M6: 2181.37 | N6: =(($E6-F6)/$E6) -> 0.011966718 | O6: =(($E6-G6)/$E6) -> -0.030576278 | P6: =(($E6-H6)/$E6) -> -0.020873815 | Q6: =(($E6-I6)/$E6) -> 0.010347904 | R6: =(($E6-J6)/$E6) -> -0.053253706 | S6: =(($E6-K6)/$E6) -> 0.012069083 | T6: =(($E6-L6)/$E6) -> 0.012979948 | U6: =(($E6-M6)/$E6) -> 0.011966718 | V6: 1759.38 | W6: 2181.25 | X6: 1827.018 | Y6: 2253.774 | Z6: 2184.847 | AA6: 2325.251 | AB6: 2181.032 | AC6: 2179.009 | AD6: 2181.25 | AE6: =Tabla13[[#This Row],[Calculated HEFT_NC]]/Tabla13[[#This Row],[Real HEFT_NC]] -> 0.79689644 | AF6: =Tabla13[[#This Row],[Calculated HEFT_DNC]]/Tabla13[[#This Row],[Real HEFT_DNC]] -> 0.99994499 | AG6: =Tabla13[[#This Row],[Calculated GA_NC]]/Tabla13[[#This Row],[Real GA_NC]] -> 0.80298036 | AH6: =Tabla13[[#This Row],[Calculated GA_DNC]]/Tabla13[[#This Row],[Real GA_DNC]] -> 0.99995519 | AI6: =Tabla13[[#This Row],[Calculated HGA_(Ph2)]]/Tabla13[[#This Row],[Real HGA_(Ph2)]] -> 0.99995561 | AJ6: =Tabla13[[#This Row],[Calculated HGA_(Ph1)]]/Tabla13[[#This Row],[Real HGA_(Ph1)]] -> 0.99995184 | AK6: =Tabla13[[#This Row],[Calculated HGA^H]]/Tabla13[[#This Row],[Real GA^H]] -> 0.99994865 | AL6: =Tabla13[[#This Row],[Calculated HGA_(Ph2)^H]]/Tabla13[[#This Row],[Real HGA_(Ph2)^H]] -> 0.9999431 | AM6: =Tabla13[[#This Row],[Calculated HGA_(Ph1)^H]]/Tabla13[[#This Row],[Real HGA_(Ph1)^H]] -> 0.99994499
A7: =LEFT(B7,FIND("-",B7)-1) -> 1000genome | B7: 1000genome-chameleon-18ch-250k-001 | C7: =_xlfn.XLOOKUP(B7,Instances!$B$2:$B$29,Instances!$A$2:$A$29,,0,1) -> 738 | D7: 1 | E7: 52760 | F7: 52760 | G7: 52760 | H7: 52760 | I7: 52760 | J7: 52760 | K7: 52760 | L7: 52760 | M7: 52760 | N7: =(($E7-F7)/$E7) -> 0 | O7: =(($E7-G7)/$E7) -> 0 | P7: =(($E7-H7)/$E7) -> 0 | Q7: =(($E7-I7)/$E7) -> 0 | R7: =(($E7-J7)/$E7) -> 0 | S7: =(($E7-K7)/$E7) -> 0 | T7: =(($E7-L7)/$E7) -> 0 | U7: =(($E7-M7)/$E7) -> 0 | V7: 42669.2 | W7: 52759.8 | X7: 42669.2 | Y7: 52759.8 | Z7: 52759.8 | AA7: 52759.8 | AB7: 52759.8 | AC7: 52759.8 | AD7: 52759.8 | AE7: =Tabla13[[#This Row],[Calculated HEFT_NC]]/Tabla13[[#This Row],[Real HEFT_NC]] -> 0.80874147 | AF7: =Tabla13[[#This Row],[Calculated HEFT_DNC]]/Tabla13[[#This Row],[Real HEFT_DNC]] -> 0.99999621 | AG7: =Tabla13[[#This Row],[Calculated GA_NC]]/Tabla13[[#This Row],[Real GA_NC]] -> 0.80874147 | AH7: =Tabla13[[#This Row],[Calculated GA_DNC]]/Tabla13[[#This Row],[Real GA_DNC]] -> 0.99999621 | AI7: =Tabla13[[#This Row],[Calculated HGA_(Ph2)]]/Tabla13[[#This Row],[Real HGA_(Ph2)]] -> 0.99999621 | AJ7: =Tabla13[[#This Row],[Calculated HGA_(Ph1)]]/Tabla13[[#This Row],[Real HGA_(Ph1)]] -> 0.99999621 | AK7: =Tabla13[[#This Row],[Calculated HGA^H]]/Tabla13[[#This Row],[Real GA^H]] -> 0.99999621 | AL7: =Tabla13[[#This Row],[Calculated HGA_(Ph2)^H]]/Tabla13[[#This Row],[Real HGA_(Ph2)^H]] -> 0.99999621 | AM7: =Tabla13[[#This Row],[Calculated HGA_(Ph1)^H]]/Tabla13[[#This Row],[Real HGA_(Ph1)^H]] -> 0.99999621
A8: =LEFT(B8,FIND("-",B8)-1) -> 1000genome | B8: 1000genome-chameleon-18ch-250k-001 | C8: =_xlfn.XLOOKUP(B8,Instances!$B$2:$B$29,Instances!$A$2:$A$29,,0,1) -> 738 | D8: 2 | E8: 26446.2 | F8: 26380.6 | G8: 26419.38 | H8: 26380.66 | I8: 26380.65 | J8: 26382.01 | K8: 26380.62 | L8: 26380.68 | M8: 26380.56 | N8: =(($E8-F8)/$E8) -> 0.0024805076 | O8: =(($E8-G8)/$E8) -> 0.0010141344 | P8: =(($E8-H8)/$E8) -> 0.0024782388 | Q8: =(($E8-I8)/$E8) -> 0.002478617 | R8: =(($E8-J8)/$E8) -> 0.0024271918 | S8: =(($E8-K8)/$E8) -> 0.0024797513 | T8: =(($E8-L8)/$E8) -> 0.0024774826 | U8: =(($E8-M8)/$E8) -> 0.0024820201 | V8: 21334.6 | W8: 26379.9 | X8: 21334.6 | Y8: 26379.9 | Z8: 26379.9 | AA8: 26381.35 | AB8: 26379.9 | AC8: 26379.9 | AD8: 26379.9 | AE8: =Tabla13[[#This Row],[Calculated HEFT_NC]]/Tabla13[[#This Row],[Real HEFT_NC]] -> 0.80671703 | AF8: =Tabla13[[#This Row],[Calculated HEFT_DNC]]/Tabla13[[#This Row],[Real HEFT_DNC]] -> 0.99997347 | AG8: =Tabla13[[#This Row],[Calculated GA_NC]]/Tabla13[[#This Row],[Real GA_NC]] -> 0.80753598 | AH8: =Tabla13[[#This Row],[Calculated GA_DNC]]/Tabla13[[#This Row],[Real GA_DNC]] -> 0.99997119 | AI8: =Tabla13[[#This Row],[Calculated HGA_(Ph2)]]/Tabla13[[#This Row],[Real HGA_(Ph2)]] -> 0.99997157 | AJ8: =Tabla13[[#This Row],[Calculated HGA_(Ph1)]]/Tabla13[[#This Row],[Real HGA_(Ph1)]] -> 0.99997498 | AK8: =Tabla13[[#This Row],[Calculated HGA^H]]/Tabla13[[#This Row],[Real GA^H]] -> 0.99997271 | AL8: =Tabla13[[#This Row],[Calculated HGA_(Ph2)^H]]/Tabla13[[#This Row],[Real HGA_(Ph2)^H]] -> 0.99997043 | AM8: =Tabla13[[#This Row],[Calculated HGA_(Ph1)^H]]/Tabla13[[#This Row],[Real HGA_(Ph1)^H]] -> 0.99997498
A9: =LEFT(B9,FIND("-",B9)-1) -> 1000genome | B9: 1000genome-chameleon-18ch-250k-001 | C9: =_xlfn.XLOOKUP(B9,Instances!$B$2:$B$29,Instances!$A$2:$A$29,,0,1) -> 738 | D9: 4 | E9: 13274.9 | F9: 13191.3 | G9: 13253.43 | H9: 13192.06 | I9: 13190.82 | J9: 13261.97 | K9: 13190.76 | L9: 13190.49 | M9: 13190.85 | N9: =(($E9-F9)/$E9) -> 0.0062975992 | O9: =(($E9-G9)/$E9) -> 0.001617338 | P9: =(($E9-H9)/$E9) -> 0.0062403483 | Q9: =(($E9-I9)/$E9) -> 0.0063337577 | R9: =(($E9-J9)/$E9) -> 0.00097401864 | S9: =(($E9-K9)/$E9) -> 0.0063382775 | T9: =(($E9-L9)/$E9) -> 0.0063586166 | U9: =(($E9-M9)/$E9) -> 0.0063314978 | V9: 10667.3 | W9: 13190.8 | X9: 10669 | Y9: 13191.61 | Z9: 13190.32 | AA9: 13261.49 | AB9: 13190.26 | AC9: 13190 | AD9: 13190.33 | AE9: =Tabla13[[#This Row],[Calculated HEFT_NC]]/Tabla13[[#This Row],[Real HEFT_NC]] -> 0.80356914 | AF9: =Tabla13[[#This Row],[Calculated HEFT_DNC]]/Tabla13[[#This Row],[Real HEFT_DNC]] -> 0.9999621 | AG9: =Tabla13[[#This Row],[Calculated GA_NC]]/Tabla13[[#This Row],[Real GA_NC]] -> 0.80499916 | AH9: =Tabla13[[#This Row],[Calculated GA_DNC]]/Tabla13[[#This Row],[Real GA_DNC]] -> 0.99996589 | AI9: =Tabla13[[#This Row],[Calculated HGA_(Ph2)]]/Tabla13[[#This Row],[Real HGA_(Ph2)]] -> 0.99996209 | AJ9: =Tabla13[[#This Row],[Calculated HGA_(Ph1)]]/Tabla13[[#This Row],[Real HGA_(Ph1)]] -> 0.99996381 | AK9: =Tabla13[[#This Row],[Calculated HGA^H]]/Tabla13[[#This Row],[Real GA^H]] -> 0.99996209 | AL9: =Tabla13[[#This Row],[Calculated HGA_(Ph2)^H]]/Tabla13[[#This Row],[Real HGA_(Ph2)^H]] -> 0.99996285 | AM9: =Tabla13[[#This Row],[Calculated HGA_(Ph1)^H]]/Tabla13[[#This Row],[Real HGA_(Ph1)^H]] -> 0.99996058
A10: =LEFT(B10,FIND("-",B10)-1) -> 1000genome | B10: 1000genome-chameleon-18ch-250k-001 | C10: =_xlfn.XLOOKUP(B10,Instances!$B$2:$B$29,Instances!$A$2:$A$29,,0,1) -> 738 | D10: 8 | E10: 6634.25 | F10: 6596.33 | G10: 6676.987 | H10: 6620.224 | I10: 6598.806 | J10: 6761.216 | K10: 6596.279 | L10: 6595.292 | M10: 6596.33 | N10: =(($E10-F10)/$E10) -> 0.005715793 | O10: =(($E10-G10)/$E10) -> -0.0064418736 | P10: =(($E10-H10)/$E10) -> 0.0021141802 | Q10: =(($E10-I10)/$E10) -> 0.0053425783 | R10: =(($E10-J10)/$E10) -> -0.019137958 | S10: =(($E10-K10)/$E10) -> 0.0057234804 | T10: =(($E10-L10)/$E10) -> 0.0058722538 | U10: =(($E10-M10)/$E10) -> 0.005715793 | V10: 5334.82 | W10: 6596.04 | X10: 5366.18 | Y10: 6619.983 | Z10: 6598.507 | AA10: 6760.938 | AB10: 6595.999 | AC10: 6594.991 | AD10: 6596.04 | AE10: =Tabla13[[#This Row],[Calculated HEFT_NC]]/Tabla13[[#This Row],[Real HEFT_NC]] -> 0.8041331 | AF10: =Tabla13[[#This Row],[Calculated HEFT_DNC]]/Tabla13[[#This Row],[Real HEFT_DNC]] -> 0.99995604 | AG10: =Tabla13[[#This Row],[Calculated GA_NC]]/Tabla13[[#This Row],[Real GA_NC]] -> 0.80368286 | AH10: =Tabla13[[#This Row],[Calculated GA_DNC]]/Tabla13[[#This Row],[Real GA_DNC]] -> 0.9999636 | AI10: =Tabla13[[#This Row],[Calculated HGA_(Ph2)]]/Tabla13[[#This Row],[Real HGA_(Ph2)]] -> 0.99995469 | AJ10: =Tabla13[[#This Row],[Calculated HGA_(Ph1)]]/Tabla13[[#This Row],[Real HGA_(Ph1)]] -> 0.99995888 | AK10: =Tabla13[[#This Row],[Calculated HGA^H]]/Tabla13[[#This Row],[Real GA^H]] -> 0.99995755 | AL10: =Tabla13[[#This Row],[Calculated HGA_(Ph2)^H]]/Tabla13[[#This Row],[Real HGA_(Ph2)^H]] -> 0.99995436 | AM10: =Tabla13[[#This Row],[Calculated HGA_(Ph1)^H]]/Tabla13[[#This Row],[Real HGA_(Ph1)^H]] -> 0.99995604
A11: =LEFT(B11,FIND("-",B11)-1) -> 1000genome | B11: 1000genome-chameleon-18ch-250k-001 | C11: =_xlfn.XLOOKUP(B11,Instances!$B$2:$B$29,Instances!$A$2:$A$29,,0,1) -> 738 | D11: 16 | E11: 3336.48 | F11: 3298.82 | G11: 3411.504 | H11: 3377.622 | I11: 3307.276 | J11: 3546.212 | K11: 3298.764 | L11: 3297.68 | M11: 3298.82 | N11: =(($E11-F11)/$E11) -> 0.011287345 | O11: =(($E11-G11)/$E11) -> -0.022485973 | P11: =(($E11-H11)/$E11) -> -0.01233096 | Q11: =(($E11-I11)/$E11) -> 0.0087529372 | R11: =(($E11-J11)/$E11) -> -0.06286026 | S11: =(($E11-K11)/$E11) -> 0.011304129 | T11: =(($E11-L11)/$E11) -> 0.011629022 | U11: =(($E11-M11)/$E11) -> 0.011287345 | V11: 2667.63 | W11: 3298.64 | X11: 2742.078 | Y11: 3377.468 | Z11: 3307.136 | AA11: 3546.019 | AB11: 3298.609 | AC11: 3297.525 | AD11: 3298.64 | AE11: =Tabla13[[#This Row],[Calculated HEFT_NC]]/Tabla13[[#This Row],[Real HEFT_NC]] -> 0.79953424 | AF11: =Tabla13[[#This Row],[Calculated HEFT_DNC]]/Tabla13[[#This Row],[Real HEFT_DNC]] -> 0.99994544 | AG11: =Tabla13[[#This Row],[Calculated GA_NC]]/Tabla13[[#This Row],[Real GA_NC]] -> 0.80377394 | AH11: =Tabla13[[#This Row],[Calculated GA_DNC]]/Tabla13[[#This Row],[Real GA_DNC]] -> 0.99995441 | AI11: =Tabla13[[#This Row],[Calculated HGA_(Ph2)]]/Tabla13[[#This Row],[Real HGA_(Ph2)]] -> 0.99995767 | AJ11: =Tabla13[[#This Row],[Calculated HGA_(Ph1)]]/Tabla13[[#This Row],[Real HGA_(Ph1)]] -> 0.99994558 | AK11: =Tabla13[[#This Row],[Calculated HGA^H]]/Tabla13[[#This Row],[Real GA^H]] -> 0.99995301 | AL11: =Tabla13[[#This Row],[Calculated HGA_(Ph2)^H]]/Tabla13[[#This Row],[Real HGA_(Ph2)^H]] -> 0.999953 | AM11: =Tabla13[[#This Row],[Calculated HGA_(Ph1)^H]]/Tabla13[[#This Row],[Real HGA_(Ph1)^H]] -> 0.99994544
A12: =LEFT(B12,FIND("-",B12)-1) -> 1000genome | B12: 1000genome-chameleon-2ch-250k-001 | C12: =_xlfn.XLOOKUP(B12,Instances!$B$2:$B$29,Instances!$A$2:$A$29,,0,1) -> 82 | D12: 1 | E12: 5545.79 | F12: 5545.79 | G12: 5545.79 | H12: 5545.79 | I12: 5545.79 | J12: 5545.79 | K12: 5545.79 | L12: 5545.79 | M12: 5545.79 | N12: =(($E12-F12)/$E12) -> 0 | O12: =(($E12-G12)/$E12) -> 0 | P12: =(($E12-H12)/$E12) -> 0 | Q12: =(($E12-I12)/$E12) -> 0 | R12: =(($E12-J12)/$E12) -> 0 | S12: =(($E12-K12)/$E12) -> 0 | T12: =(($E12-L12)/$E12) -> 0 | U12: =(($E12-M12)/$E12) -> 0 | V12: 4436.46 | W12: 5545.77 | X12: 4436.46 | Y12: 5545.77 | Z12: 5545.77 | AA12: 5545.77 | AB12: 5545.77 | AC12: 5545.77 | AD12: 5545.77 | AE12: =Tabla13[[#This Row],[Calculated HEFT_NC]]/Tabla13[[#This Row],[Real HEFT_NC]] -> 0.79996899 | AF12: =Tabla13[[#This Row],[Calculated HEFT_DNC]]/Tabla13[[#This Row],[Real HEFT_DNC]] -> 0.99999639 | AG12: =Tabla13[[#This Row],[Calculated GA_NC]]/Tabla13[[#This Row],[Real GA_NC]] -> 0.79996899 | AH12: =Tabla13[[#This Row],[Calculated GA_DNC]]/Tabla13[[#This Row],[Real GA_DNC]] -> 0.99999639 | AI12: =Tabla13[[#This Row],[Calculated HGA_(Ph2)]]/Tabla13[[#This Row],[Real HGA_(Ph2)]] -> 0.99999639 | AJ12: =Tabla13[[#This Row],[Calculated HGA_(Ph1)]]/Tabla13[[#This Row],[Real HGA_(Ph1)]] -> 0.99999639 | AK12: =Tabla13[[#This Row],[Calculated HGA^H]]/Tabla13[[#This Row],[Real GA^H]] -> 0.99999639 | AL12: =Tabla13[[#This Row],[Calculated HGA_(Ph2)^H]]/Tabla13[[#This Row],[Real HGA_(Ph2)^H]] -> 0.99999639 | AM12: =Tabla13[[#This Row],[Calculated HGA_(Ph1)^H]]/Tabla13[[#This Row],[Real HGA_(Ph1)^H]] -> 0.99999639
A13: =LEFT(B13,FIND("-",B13)-1) -> 1000genome | B13: 1000genome-chameleon-2ch-250k-001 | C13: =_xlfn.XLOOKUP(B13,Instances!$B$2:$B$29,Instances!$A$2:$A$29,,0,1) -> 82 | D13: 2 | E13: 2775.43 | F13: 2773.1 | G13: 2778.313 | H13: 2772.935 | I13: 2772.94 | J13: 2772.921 | K13: 2772.93 | L13: 2772.937 | M13: 2772.921 | N13: =(($E13-F13)/$E13) -> 0.00083950955 | O13: =(($E13-G13)/$E13) -> -0.001038758 | P13: =(($E13-H13)/$E13) -> 0.0008989598 | Q13: =(($E13-I13)/$E13) -> 0.00089715828 | R13: =(($E13-J13)/$E13) -> 0.00090400406 | S13: =(($E13-K13)/$E13) -> 0.00090076132 | T13: =(($E13-L13)/$E13) -> 0.00089823919 | U13: =(($E13-M13)/$E13) -> 0.00090400406 | V13: 2218.37 | W13: 2773.05 | X13: 2218.231 | Y13: 2772.89 | Z13: 2772.89 | AA13: 2772.89 | AB13: 2772.89 | AC13: 2772.89 | AD13: 2772.89 | AE13: =Tabla13[[#This Row],[Calculated HEFT_NC]]/Tabla13[[#This Row],[Real HEFT_NC]] -> 0.79928876 | AF13: =Tabla13[[#This Row],[Calculated HEFT_DNC]]/Tabla13[[#This Row],[Real HEFT_DNC]] -> 0.99998197 | AG13: =Tabla13[[#This Row],[Calculated GA_NC]]/Tabla13[[#This Row],[Real GA_NC]] -> 0.79840932 | AH13: =Tabla13[[#This Row],[Calculated GA_DNC]]/Tabla13[[#This Row],[Real GA_DNC]] -> 0.99998377 | AI13: =Tabla13[[#This Row],[Calculated HGA_(Ph2)]]/Tabla13[[#This Row],[Real HGA_(Ph2)]] -> 0.99998197 | AJ13: =Tabla13[[#This Row],[Calculated HGA_(Ph1)]]/Tabla13[[#This Row],[Real HGA_(Ph1)]] -> 0.99998882 | AK13: =Tabla13[[#This Row],[Calculated HGA^H]]/Tabla13[[#This Row],[Real GA^H]] -> 0.99998557 | AL13: =Tabla13[[#This Row],[Calculated HGA_(Ph2)^H]]/Tabla13[[#This Row],[Real HGA_(Ph2)^H]] -> 0.99998305 | AM13: =Tabla13[[#This Row],[Calculated HGA_(Ph1)^H]]/Tabla13[[#This Row],[Real HGA_(Ph1)^H]] -> 0.99998882
... A141: =LEFT(B141,FIND("-",B141)-1) -> srasearch | B141: srasearch-chameleon-50a-003 | C141: =_xlfn.XLOOKUP(B141,Instances!$B$2:$B$29,Instances!$A$2:$A$29,,0,1) -> 104 | D141: 16 | E141: 3781.2 | F141: 3760.71 | G141: 4027.174 | H141: 4030.899 | I141: 3738.737 | J141: 4112.416 | K141: 3774.319 | L141: 3742.143 | M141: 3760.71 | N141: =(($E141-F141)/$E141) -> 0.0054189146 | O141: =(($E141-G141)/$E141) -> -0.065051835 | P141: =(($E141-H141)/$E141) -> -0.066036972 | Q141: =(($E141-I141)/$E141) -> 0.011230033 | R141: =(($E141-J141)/$E141) -> -0.087595472 | S141: =(($E141-K141)/$E141) -> 0.0018197927 | T141: =(($E141-L141)/$E141) -> 0.010329261 | U141: =(($E141-M141)/$E141) -> 0.0054189146 | V141: 3732.21 | W141: 3760.08 | X141: 3958.583 | Y141: 4029.482 | Z141: 3712.719 | AA141: 4099.419 | AB141: 3760.08 | AC141: 3699.776 | AD141: 3760.08 | AE141: =Tabla13[[#This Row],[Calculated HEFT_NC]]/Tabla13[[#This Row],[Real HEFT_NC]] -> 0.9870438 | AF141: =Tabla13[[#This Row],[Calculated HEFT_DNC]]/Tabla13[[#This Row],[Real HEFT_DNC]] -> 0.99983248 | AG141: =Tabla13[[#This Row],[Calculated GA_NC]]/Tabla13[[#This Row],[Real GA_NC]] -> 0.98296796 | AH141: =Tabla13[[#This Row],[Calculated GA_DNC]]/Tabla13[[#This Row],[Real GA_DNC]] -> 0.99964847 | AI141: =Tabla13[[#This Row],[Calculated HGA_(Ph2)]]/Tabla13[[#This Row],[Real HGA_(Ph2)]] -> 0.99304097 | AJ141: =Tabla13[[#This Row],[Calculated HGA_(Ph1)]]/Tabla13[[#This Row],[Real HGA_(Ph1)]] -> 0.99683957 | AK141: =Tabla13[[#This Row],[Calculated HGA^H]]/Tabla13[[#This Row],[Real GA^H]] -> 0.9962274 | AL141: =Tabla13[[#This Row],[Calculated HGA_(Ph2)^H]]/Tabla13[[#This Row],[Real HGA_(Ph2)^H]] -> 0.98867841 | AM141: =Tabla13[[#This Row],[Calculated HGA_(Ph1)^H]]/Tabla13[[#This Row],[Real HGA_(Ph1)^H]] -> 0.99983248
T142: =COUNTIF(#REF!, "<0") -> #REF! | U142: =COUNTIF(#REF!, "<0") -> #REF! | V142: =COUNTIF(#REF!, "<0") -> #REF! | W142: =COUNTIF(#REF!, "<0") -> #REF! | X142: =COUNTIF(#REF!, ">0") -> #REF!
T143: =COUNTIF(#REF!, ">0") -> #REF! | U143: =COUNTIF(#REF!, ">0") -> #REF! | V143: =COUNTIF(#REF!, ">0") -> #REF! | W143: =COUNTIF(#REF!, ">0") -> #REF! | X143: =COUNTIF(#REF!, "<0") -> #REF!

Sheet Accuracy
M1: Global Accuracy (the worst of all Xhosts configurations)
A3: Etiquetas de fila | B3: HEFT_NC | C3: HEFT_DNC | D3: GA_NC | E3: GA_DNC | F3: HGA_(Ph1) | G3: HGA_(Ph2) | H3: HGA^H | I3: HGA_(Ph1)^H | J3: HGA_(Ph2)^H | M3: HEFT_NC | N3: HEFT_DNC | O3: GA_NC | P3: GA_DNC | Q3: HGA_(Ph1) | R3: HGA_(Ph2) | S3: HGA^H | T3: HGA_(Ph1)^H | U3: HGA_(Ph2)^H
A4: seismology | L4: =A4 -> seismology | M4: =MIN(B5,B6,B7,B8,B9) -> 0.99655311 | N4: =MIN(C5,C6,C7,C8,C9) -> 0.99840084 | O4: =MIN(D5,D6,D7,D8,D9) -> 0.99659687 | P4: =MIN(E5,E6,E7,E8,E9) -> 0.9984153 | Q4: =MIN(F5,F6,F7,F8,F9) -> 0.99844765 | R4: =MIN(G5,G6,G7,G8,G9) -> 0.99839074 | S4: =MIN(H5,H6,H7,H8,H9) -> 0.9984006 | T4: =MIN(I5,I6,I7,I8,I9) -> 0.99840084 | U4: =MIN(J5,J6,J7,J8,J9) -> 0.99838826
A5: 1 | B5: 0.99965774 | C5: 0.99999445 | D5: 0.99965774 | E5: 0.99999445 | F5: 0.99999445 | G5: 0.99999445 | H5: 0.99999445 | I5: 0.99999445 | J5: 0.99999445
A6: 2 | B6: 0.99944597 | C6: 0.99988908 | D6: 0.99944355 | E6: 0.99988592 | F6: 0.99988601 | G6: 0.99988645 | H6: 0.99988584 | I6: 0.99988625 | J6: 0.99988658
A7: 4 | B7: 0.99902452 | C7: 0.99967165 | D7: 0.99902773 | E7: 0.99967276 | F7: 0.9996721 | G7: 0.99967129 | H7: 0.99967208 | I7: 0.99967268 | J7: 0.99967115
A8: 8 | B8: 0.99819237 | C8: 0.9992473 | D8: 0.99820571 | E8: 0.99924453 | F8: 0.99925025 | G8: 0.99923823 | H8: 0.99924355 | I8: 0.99924652 | J8: 0.99924195
A9: 16 | B9: 0.99655311 | C9: 0.99840084 | D9: 0.99659687 | E9: 0.9984153 | F9: 0.99844765 | G9: 0.99839074 | H9: 0.9984006 | I9: 0.99840084 | J9: 0.99838826
A10: cycles | L10: =A10 -> cycles | M10: =MIN(B11,B12,B13,B14,B15) -> 0.99590125 | N10: =MIN(C11,C12,C13,C14,C15) -> 0.99994626 | O10: =MIN(D11,D12,D13,D14,D15) -> 0.99569796 | P10: =MIN(E11,E12,E13,E14,E15) -> 0.99994524 | Q10: =MIN(F11,F12,F13,F14,F15) -> 0.99994215 | R10: =MIN(G11,G12,G13,G14,G15) -> 0.99994143 | S10: =MIN(H11,H12,H13,H14,H15) -> 0.99994268 | T10: =MIN(I11,I12,I13,I14,I15) -> 0.99994236 | U10: =MIN(J11,J12,J13,J14,J15) -> 0.99994113
A11: 1 | B11: 0.99590125 | C11: 0.99995145 | D11: 0.99590125 | E11: 0.99995145 | F11: 0.99995145 | G11: 0.99995145 | H11: 0.99995145 | I11: 0.99995145 | J11: 0.99995145
A12: 2 | B12: 0.99597899 | C12: 0.99994626 | D12: 0.99569796 | E12: 0.99994524 | F12: 0.99994215 | G12: 0.99994143 | H12: 0.99994268 | I12: 0.99994236 | J12: 0.99994113
A13: 4 | B13: 0.99634343 | C13: 0.99994703 | D13: 0.99639498 | E13: 0.99994915 | F13: 0.99994535 | G13: 0.99994804 | H13: 0.99994742 | I13: 0.9999445 | J13: 0.99994524
A14: 8 | B14: 0.99660337 | C14: 0.99994965 | D14: 0.99683364 | E14: 0.99995373 | F14: 0.99994792 | G14: 0.99995137 | H14: 0.99994877 | I14: 0.99994965 | J14: 0.99994442
A15: 16 | B15: 0.99737498 | C15: 0.99995663 | D15: 0.99765054 | E15: 0.99995831 | F15: 0.99994742 | G15: 0.99995588 | H15: 0.99995492 | I15: 0.99995586 | J15: 0.99995341
A16: epigenomics | L16: =A16 -> epigenomics | M16: =MIN(B17,B18,B19,B20,B21) -> 0.95465718 | N16: =MIN(C17,C18,C19,C20,C21) -> 0.99107092 | O16: =MIN(D17,D18,D19,D20,D21) -> 0.95691955 | P16: =MIN(E17,E18,E19,E20,E21) -> 0.9887196 | Q16: =MIN(F17,F18,F19,F20,F21) -> 0.9916525 | R16: =MIN(G17,G18,G19,G20,G21) -> 0.98805873 | S16: =MIN(H17,H18,H19,H20,H21) -> 0.98817446 | T16: =MIN(I17,I18,I19,I20,I21) -> 0.99044055 | U16: =MIN(J17,J18,J19,J20,J21) -> 0.98760434
A17: 1 | B17: 0.98222985 | C17: 0.99991469 | D17: 0.9822289 | E17: 0.99991469 | F17: 0.99991469 | G17: 0.99991469 | H17: 0.99991469 | I17: 0.99991469 | J17: 0.99991469
A18: 2 | B18: 0.97841506 | C18: 0.99792703 | D18: 0.97897363 | E18: 0.99771874 | F18: 0.99763285 | G18: 0.99786136 | H18: 0.99771143 | I18: 0.99782116 | J18: 0.99796962
A19: 4 | B19: 0.97258694 | C19: 0.99586742 | D19: 0.97419692 | E19: 0.99618974 | F19: 0.99602647 | G19: 0.99682776 | H19: 0.99622833 | I19: 0.99576997 | J19: 0.99677776
A20: 8 | B20: 0.96578146 | C20: 0.99391336 | D20: 0.96722242 | E20: 0.99450248 | F20: 0.99448371 | G20: 0.99475983 | H20: 0.99394773 | I20: 0.99339834 | J20: 0.99474173
A21: 16 | B21: 0.95465718 | C21: 0.99107092 | D21: 0.95691955 | E21: 0.9887196 | F21: 0.9916525 | G21: 0.98805873 | H21: 0.98817446 | I21: 0.99044055 | J21: 0.98760434
A22: srasearch | L22: =A22 -> srasearch | M22: =MIN(B23,B24,B25,B26,B27) -> 0.96817147 | N22: =MIN(C23,C24,C25,C26,C27) -> 0.99396195 | O22: =MIN(D23,D24,D25,D26,D27) -> 0.96092647 | P22: =MIN(E23,E24,E25,E26,E27) -> 0.99657061 | Q22: =MIN(F23,F24,F25,F26,F27) -> 0.99497343 | R22: =MIN(G23,G24,G25,G26,G27) -> 0.99337603 | S22: =MIN(H23,H24,H25,H26,H27) -> 0.99394467 | T22: =MIN(I23,I24,I25,I26,I27) -> 0.99258518 | U22: =MIN(J23,J24,J25,J26,J27) -> 0.99341435
A23: 1 | B23: 0.97211697 | C23: 0.99999629 | D23: 0.97211697 | E23: 0.99999629 | F23: 0.99999629 | G23: 0.99999629 | H23: 0.99999629 | I23: 0.99999629 | J23: 0.99999629
A24: 2 | B24: 0.96817147 | C24: 0.99581179 | D24: 0.9676736 | E24: 0.99832045 | F24: 0.99534762 | G24: 0.99725497 | H24: 0.99792429 | I24: 0.99593678 | J24: 0.99672272
A25: 4 | B25: 0.97391817 | C25: 0.99696192 | D25: 0.96092647 | E25: 0.99657061 | F25: 0.99606009 | G25: 0.99337603 | H25: 0.99478797 | I25: 0.99657731 | J25: 0.99341435
A26: 8 | B26: 0.97232897 | C26: 0.99396195 | D26: 0.97135128 | E26: 0.99783552 | F26: 0.99497343 | G26: 0.99516067 | H26: 0.99394467 | I26: 0.99258518 | J26: 0.99418021
A27: 16 | B27: 0.97278162 | C27: 0.99882152 | D27: 0.97153217 | E27: 0.9967375 | F27: 0.99531946 | G27: 0.9956381 | H27: 0.99484443 | I27: 0.99545655 | J27: 0.99396531
A28: montage | L28: =A28 -> montage | M28: =MIN(B29,B30,B31,B32,B33) -> 0.86970585 | N28: =MIN(C29,C30,C31,C32,C33) -> 0.94897298 | O28: =MIN(D29,D30,D31,D32,D33) -> 0.92359435 | P28: =MIN(E29,E30,E31,E32,E33) -> 0.9590475 | Q28: =MIN(F29,F30,F31,F32,F33) -> 0.95082338 | R28: =MIN(G29,G30,G31,G32,G33) -> 0.94912681 | S28: =MIN(H29,H30,H31,H32,H33) -> 0.95041437 | T28: =MIN(I29,I30,I31,I32,I33) -> 0.9462381 | U28: =MIN(J29,J30,J31,J32,J33) -> 0.94514259
A29: 1 | B29: 0.96429151 | C29: 0.99979053 | D29: 0.96429151 | E29: 0.99979053 | F29: 0.99979053 | G29: 0.99979053 | H29: 0.99979053 | I29: 0.99979053 | J29: 0.99979053
A30: 2 | B30: 0.94665034 | C30: 0.98102977 | D30: 0.94227983 | E30: 0.98247058 | F30: 0.98163842 | G30: 0.98187732 | H30: 0.97971501 | I30: 0.98124343 | J30: 0.97905161
A31: 4 | B31: 0.92659921 | C31: 0.96576869 | D31: 0.93755795 | E31: 0.97097652 | F31: 0.96781285 | G31: 0.97124247 | H31: 0.96631485 | I31: 0.96559563 | J31: 0.96778169
A32: 8 | B32: 0.88666768 | C32: 0.95157749 | D32: 0.92735119 | E32: 0.96307063 | F32: 0.9582209 | G32: 0.96203892 | H32: 0.95604396 | I32: 0.95157749 | J32: 0.95635457
A33: 16 | B33: 0.86970585 | C33: 0.94897298 | D33: 0.92359435 | E33: 0.9590475 | F33: 0.95082338 | G33: 0.94912681 | H33: 0.95041437 | I33: 0.9462381 | J33: 0.94514259
A34: soykb | L34: =A34 -> soykb | M34: =MIN(B35,B36,B37,B38,B39) -> 0.87076148 | N34: =MIN(C35,C36,C37,C38,C39) -> 0.99997584 | O34: =MIN(D35,D36,D37,D38,D39) -> 0.87076148 | P34: =MIN(E35,E36,E37,E38,E39) -> 0.99997749 | Q34: =MIN(F35,F36,F37,F38,F39) -> 0.99997842 | R34: =MIN(G35,G36,G37,G38,G39) -> 0.99997528 | S34: =MIN(H35,H36,H37,H38,H39) -> 0.99997689 | T34: =MIN(I35,I36,I37,I38,I39) -> 0.99997584 | U34: =MIN(J35,J36,J37,J38,J39) -> 0.99997417
A35: 1 | B35: 0.87076148 | C35: 0.99998808 | D35: 0.87076148 | E35: 0.99998808 | F35: 0.99998808 | G35: 0.99998808 | H35: 0.99998808 | I35: 0.99998808 | J35: 0.99998808
A36: 2 | B36: 0.89616675 | C36: 0.99998194 | D36: 0.89470286 | E36: 0.99997978 | F36: 0.99998039 | G36: 0.99997934 | H36: 0.99997956 | I36: 0.99998141 | J36: 0.99997901
A37: 4 | B37: 0.92071866 | C37: 0.9999773 | D37: 0.92068658 | E37: 0.99997816 | F37: 0.9999787 | G37: 0.99997776 | H37: 0.99997689 | I37: 0.9999773 | J37: 0.99997633
A38: 8 | B38: 0.94664943 | C38: 0.99997584 | D38: 0.94402482 | E38: 0.99997749 | F38: 0.99997914 | G38: 0.99997582 | H38: 0.99997709 | I38: 0.99997584 | J38: 0.99997463
A39: 16 | B39: 0.96223384 | C39: 0.99997799 | D39: 0.96011037 | E39: 0.99997831 | F39: 0.99997842 | G39: 0.99997528 | H39: 0.99997837 | I39: 0.99997799 | J39: 0.99997417
A40: 1000genome | L40: =A40 -> 1000genome | M40: =MIN(B41,B42,B43,B44,B45) -> 0.81336256 | N40: =MIN(C41,C42,C43,C44,C45) -> 0.99994632 | O40: =MIN(D41,D42,D43,D44,D45) -> 0.8078577 | P40: =MIN(E41,E42,E43,E44,E45) -> 0.99992806 | Q40: =MIN(F41,F42,F43,F44,F45) -> 0.999935 | R40: =MIN(G41,G42,G43,G44,G45) -> 0.9999498 | S40: =MIN(H41,H42,H43,H44,H45) -> 0.99995871 | T40: =MIN(I41,I42,I43,I44,I45) -> 0.99994557 | U40: =MIN(J41,J42,J43,J44,J45) -> 0.99993881
A41: 1 | B41: 0.81451831 | C41: 0.99999743 | D41: 0.81451831 | E41: 0.99999743 | F41: 0.99999743 | G41: 0.99999743 | H41: 0.99999743 | I41: 0.99999743 | J41: 0.99999743
...

Sheet Makespan MPE
A3: Etiquetas de fila | B3: HEFT_DNC | C3: GA_NC | D3: GA_DNC | E3: HGA_(Ph1) | F3: HGA_(Ph2) | G3: GA^H | H3: HGA_(Ph1)^H | I3: HGA_(Ph2)^H
A4: 1000genome
A5: 2 | B5: 0.0013995846 | C5: -0.00043101962 | D5: 0.0014363893 | E5: 0.0014248913 | F5: 0.0014352196 | G5: 0.0014378965 | H5: 0.0014392441 | I5: 0.0014357353
A6: 4 | B6: 0.0043083845 | C6: 0.00023830022 | D6: 0.007879554 | E6: 0.0014074481 | F6: 0.0097062255 | G6: 0.0079758389 | H6: 0.0057902415 | I6: 0.0097575601
A7: 8 | B7: 0.0024616194 | C7: 0.014104187 | D7: 0.02170215 | E7: -0.011356137 | F7: 0.03777819 | G7: 0.031809063 | H7: 0.0036365812 | I7: 0.038309154
A8: 16 | B8: 0.0058135156 | C8: -0.028396883 | D8: -0.017132505 | E8: -0.042307295 | F8: 0.023184854 | G8: 0.015444737 | H8: 0.0058250376 | I8: 0.026769322
A9: cycles
A10: 2 | B10: -0.00024959148 | C10: -0.0035035099 | D10: -0.0034732553 | E10: 0.00062592945 | F10: -0.00088946268 | G10: 0.00075503861 | H10: 0.0006834751 | I10: 0.00077069282
A11: 4 | B11: -2.9847327e-06 | C11: -0.030428571 | D11: -0.030090657 | E11: -0.017306444 | F11: -0.028142196 | G11: 0.0015702555 | H11: 0.0013248402 | I11: 0.0027346073
A12: 8 | B12: 7.8282772e-05 | C12: -0.076353352 | D12: -0.081456644 | E12: -0.073006806 | F12: -0.061911895 | G12: 0.0056041689 | H12: 7.8282772e-05 | I12: 0.012284647
A13: 16 | B13: 8.328918e-05 | C13: -0.16751738 | D13: -0.17677059 | E13: -0.15568699 | F13: -0.12281806 | G13: 0.00017186378 | H13: 8.2525336e-05 | I13: 0.0068694771
A14: epigenomics
A15: 2 | B15: 0.00094141383 | C15: 0.017787861 | D15: 0.018182561 | E15: -0.018961905 | F15: 0.018401816 | G15: 0.018170247 | H15: 0.004509792 | I15: 0.018268395
A16: 4 | B16: 0.00070825633 | C16: 0.031114085 | D16: 0.02694164 | E16: -0.11996769 | F16: 0.039608953 | G16: 0.025869381 | H16: 0.0017599284 | I16: 0.039560848
A17: 8 | B17: 0.00065801361 | C17: 0.028636141 | D17: 0.024743187 | E17: -0.28823382 | F17: 0.061850772 | G17: 0.028296508 | H17: 0.003628141 | I17: 0.062434871
A18: 16 | B18: 0.0017607191 | C18: -0.0059955302 | D18: -0.0053137123 | E18: -0.37881063 | F18: 0.074312622 | G18: 0.0055784699 | H18: 0.0011234061 | I18: 0.07501493
A19: montage
A20: 2 | B20: 0.0023851463 | C20: 0.0024808077 | D20: 0.0094188395 | E20: 0.0052065755 | F20: 0.0089358563 | G20: 0.0067104885 | H20: 0.0047980073 | I20: 0.006092601
A21: 4 | B21: 0.0073659369 | C21: 0.0076061713 | D21: 0.013060907 | E21: 0.0024698059 | F21: 0.023245653 | G21: 0.014567759 | H21: 0.0072388304 | I21: 0.019985605
A22: 8 | B22: 0.037990789 | C22: 0.017299372 | D22: 0.021017506 | E22: 0.01622253 | F22: 0.054822125 | G22: 0.047146108 | H22: 0.037990789 | I22: 0.050029454
A23: 16 | B23: 0.047926021 | C23: 0.0077925692 | D23: 0.0063742828 | E23: 0.016970592 | F23: 0.058612452 | G23: 0.053034111 | H23: 0.045115568 | I23: 0.05797351
A24: seismology
A25: 2 | B25: 2.3313626e-07 | C25: 7.6979811e-05 | D25: 8.2563936e-05 | E25: 8.265589e-05 | F25: 8.3093892e-05 | G25: 8.2067097e-05 | H25: 8.2897493e-05 | I25: 8.3223145e-05
A26: 4 | B26: 3.8093746e-06 | C26: 0.00010150918 | D26: 0.00010948435 | E26: -0.00067541517 | F26: 0.00044576247 | G26: 0.00035959832 | H26: 0.00013904955 | I26: 0.00045246411
A27: 8 | B27: 2.136963e-05 | C27: 0.00052954721 | D27: 0.00045406065 | E27: -0.0109941 | F27: 0.0022141004 | G27: 0.00095975465 | H27: 8.4682128e-05 | I27: 0.0024787612
A28: 16 | B28: 4.3732556e-06 | C28: -0.0086007089 | D28: -0.0083285029 | E28: -0.033637905 | F28: 0.00075944353 | G28: 8.2457794e-05 | H28: 4.3732556e-06 | I28: 0.0034117738
A29: soykb
A30: 2 | B30: 0.0021844873 | C30: 0.00028951703 | D30: 0.0036881014 | E30: -0.0042360518 | F30: 0.0044532199 | G30: 0.0044572289 | H30: 0.0029067238 | I30: 0.004457319
A31: 4 | B31: 0.0048419508 | C31: 0.00010597401 | D31: 0.0056491193 | E31: -0.004805992 | F31: 0.0079642227 | G31: 0.0068922465 | H31: 0.0048419508 | I31: 0.0080412621
A32: 8 | B32: 0.00080789966 | C32: -0.0018575799 | D32: 0.0016184721 | E32: -0.0075602532 | F32: 0.0085819665 | G32: 0.003541974 | H32: 0.00080789966 | I32: 0.0088363128
A33: 16 | B33: 0.00021425276 | C33: -0.0064948758 | D33: -0.0035842211 | E33: -0.0094950461 | F33: 0.0093117502 | G33: 0.001852957 | H33: 0.00021425276 | I33: 0.0097180781
A34: srasearch
A35: 2 | B35: 0.00042933908 | C35: 0.00020715948 | D35: 0.0031318997 | E35: 0.0001354979 | F35: 0.0020721668 | G35: 0.0027363764 | H35: 0.0007269521 | I35: 0.0015395468
A36: 4 | B36: 0.00087297188 | C36: -0.00010651967 | D36: 0.011838328 | E36: 0.0042857981 | F36: 0.010640546 | G36: 0.009854628 | H36: 0.0072893637 | I36: 0.010732495
A37: 8 | B37: 0.0027711052 | C37: -0.020613927 | D37: -0.017080394 | E37: -0.019462791 | F37: 0.0073246764 | G37: 0.0038670981 | H37: 0.0013863327 | I37: 0.0066186041
A38: 16 | B38: 0.0017579367 | C38: -0.04118001 | D38: -0.048296229 | E38: -0.040728854 | F38: 0.0059150742 | G38: -0.0022403828 | H38: -0.0016460821 | I38: 0.0057272932
